Traceback (most recent call last):
  File "/home/runner/micromamba/envs/python_software_dev/lib/python3.12/site-packages/jupyter_cache/executors/utils.py", line 58, in single_nb_execution
    executenb(
  File "/home/runner/micromamba/envs/python_software_dev/lib/python3.12/site-packages/nbclient/client.py", line 1319, in execute
    return NotebookClient(nb=nb, resources=resources, km=km, **kwargs).execute()
           ^^^^^^^^^^^^^^^^^^^^^^^^^^^^^^^^^^^^^^^^^^^^^^^^^^^^^^^^^^^^^^^^^^^^^
  File "/home/runner/micromamba/envs/python_software_dev/lib/python3.12/site-packages/jupyter_core/utils/__init__.py", line 165, in wrapped
    return loop.run_until_complete(inner)
           ^^^^^^^^^^^^^^^^^^^^^^^^^^^^^^
  File "/home/runner/micromamba/envs/python_software_dev/lib/python3.12/asyncio/base_events.py", line 691, in run_until_complete
    return future.result()
           ^^^^^^^^^^^^^^^
  File "/home/runner/micromamba/envs/python_software_dev/lib/python3.12/site-packages/nbclient/client.py", line 709, in async_execute
    await self.async_execute_cell(
  File "/home/runner/micromamba/envs/python_software_dev/lib/python3.12/site-packages/nbclient/client.py", line 1062, in async_execute_cell
    await self._check_raise_for_error(cell, cell_index, exec_reply)
  File "/home/runner/micromamba/envs/python_software_dev/lib/python3.12/site-packages/nbclient/client.py", line 918, in _check_raise_for_error
    raise CellExecutionError.from_cell_and_msg(cell, exec_reply_content)
nbclient.exceptions.CellExecutionError: An error occurred while executing the following cell:
------------------
import pandas as pd

df = pd.DataFrame({"A": [2, 3, 4, 5],
                   "B": [0, -1, 0, -5],
                  })

@numba.jit(nopython=True)
def get_max(df):
    return df.max()

get_max(df)
------------------


[31m---------------------------------------------------------------------------[39m
[31mTypingError[39m                               Traceback (most recent call last)
[36mCell[39m[36m [39m[32mIn[10][39m[32m, line 11[39m
[32m      7[39m [38;5;129m@numba[39m.jit(nopython=[38;5;28;01mTrue[39;00m)
[32m      8[39m [38;5;28;01mdef[39;00m[38;5;250m [39m[34mget_max[39m(df):
[32m      9[39m     [38;5;28;01mreturn[39;00m df.max()
[32m---> [39m[32m11[39m [43mget_max[49m[43m([49m[43mdf[49m[43m)[49m

[36mFile [39m[32m~/micromamba/envs/python_software_dev/lib/python3.12/site-packages/numba/core/dispatcher.py:424[39m, in [36m_DispatcherBase._compile_for_args[39m[34m(self, *args, **kws)[39m
[32m    420[39m         msg = ([33mf[39m[33m"[39m[38;5;132;01m{[39;00m[38;5;28mstr[39m(e).rstrip()[38;5;132;01m}[39;00m[33m [39m[38;5;130;01m\n[39;00m[38;5;130;01m\n[39;00m[33mThis error may have been caused [39m[33m"[39m
[32m    421[39m                [33mf[39m[33m"[39m[33mby the following argument(s):[39m[38;5;130;01m\n[39;00m[38;5;132;01m{[39;00margs_str[38;5;132;01m}[39;00m[38;5;130;01m\n[39;00m[33m"[39m)
[32m    422[39m         e.patch_message(msg)
[32m--> [39m[32m424[39m     [43merror_rewrite[49m[43m([49m[43me[49m[43m,[49m[43m [49m[33;43m'[39;49m[33;43mtyping[39;49m[33;43m'[39;49m[43m)[49m
[32m    425[39m [38;5;28;01mexcept[39;00m errors.UnsupportedError [38;5;28;01mas[39;00m e:
[32m    426[39m     [38;5;66;03m# Something unsupported is present in the user code, add help info[39;00m
[32m    427[39m     error_rewrite(e, [33m'[39m[33munsupported_error[39m[33m'[39m)

[36mFile [39m[32m~/micromamba/envs/python_software_dev/lib/python3.12/site-packages/numba/core/dispatcher.py:365[39m, in [36m_DispatcherBase._compile_for_args.<locals>.error_rewrite[39m[34m(e, issue_type)[39m
[32m    363[39m     [38;5;28;01mraise[39;00m e
[32m    364[39m [38;5;28;01melse[39;00m:
[32m--> [39m[32m365[39m     [38;5;28;01mraise[39;00m e.with_traceback([38;5;28;01mNone[39;00m)

[31mTypingError[39m: Failed in nopython mode pipeline (step: nopython frontend)
[1m[1m[1mnon-precise type pyobject[0m
[0m[1mDuring: typing of argument at /tmp/ipykernel_3609/1526091316.py (7)[0m
[1m
File "../../../../../../tmp/ipykernel_3609/1526091316.py", line 7:[0m
[1m<source missing, REPL/exec in use?>[0m

[0m[1mDuring: Pass nopython_type_inference[0m 

This error may have been caused by the following argument(s):
- argument 0: [1mCannot determine Numba type of <class 'pandas.core.frame.DataFrame'>[0m


